> [!warning|badge]
> При работе с асинхронным кодом, Jest нужно знать когда тестируемый код завершен, чтобы перейти к следующему тесту. 

# Промисы

> [!note|badge]
> Если вернуть промис из теста, Jest будет ждать разрешения этого промиса, если он будет отклонен, тест провалится.

```ts
async function fetchData() {
  return Promise.resolve('peanut butter');
}  

test('the data is peanut butter', () => {
  return fetchData().then((data) => {
    expect(data).toBe('peanut butter');
  });
});
```

> [!tip|badge]
> Как мы знаем, асинхронные функции автоматически возвращают промис (синтаксис async/await):

```ts
test('the data is peanut butter', async () => {
  const data = await fetchData();
  expect(data).toBe('peanut butter');
});
```

## Проверки в случае отклонения промиса

> [!warning|badge]
> Если промис успешно выполнится, логично, что и тест тогда будет пройден. Но, что если мы хотим убедиться, что промис будет отклонен, и в `catch` проверить ошибку.

> [!tip|badge]
> Чтобы убедится в том, что в ходе теста было выполнено определенное кол-во проверок - надо использовать метод `except.assertions`:

```ts
async function fetchData() {
  throw 'error';
}

test('the fetch fails with an error', () => {
  expect.assertions(1);
  return fetchData().catch((error) => expect(error).toMatch('error'));
});

//или

test('the fetch fails with an error', async () => {
  expect.assertions(1);
  try {
    await fetchData();
  } catch (error) {
    expect(error).toMatch('error');
  }
});
```

## `.resolves` и `.rejects` - альтернатива использованию `except.assertions`

```ts
test('the data is peanut butter', () => {
  return expect(fetchData()).resolves.toBe('peanut butter');
});

// или

test('the data is peanut butter', async () => {
  await expect(fetchData()).resolves.toBe('peanut butter');
});
```

```ts
test('the fetch fails with an error', async () => {
  await expect(fetchData()).rejects.toMatch('error');
});
```

# Если нужно использовать асинхронные коллбэки

> [!note|badge]
> Если использовать первый аргумент - коллбэк (принято называть "done"), Jest будет ждать его вызова, чтобы завершить тест.

> [!danger|badge]
> Jest выбросит исключение, если тестовая функция использует первый аргумент и возвращает промис.

```ts
type Cb = (error: {} | null, data: any) => void;

function fetchData(cb: Cb) {
  setTimeout(() => cb(null, 'peanut butter'), 1000);
}

test('the data is peanut butter', (done) => {
  function callback(error: {} | null, data: string) {
    if (error) {
      done(error);
      return;
    }

    try {
      expect(data).toBe('peanut butter');
      done();
    } catch (error) {
      done(error);
    }
  }

  fetchData(callback);
});
```

> [!note|badge]
> Если в done передать аргумент, то тест провалится.

> [!warning|badge]
> Если done не будет вызван, то тест в итоге через какое то время провалится.

![[Pasted image 20250102214128.png]]

> [!warning|badge]
> Если какая то проверка провалится - будет выброшено исключение, соответственно done не будет вызван. В таком случае тест уже провалился, но придется ждать окончания таймаута, поэтому проверки в асинхронных коллбэках стоит оборачивать в `try catch`, чтобы в `catch` передать эту ошибку в done.

```ts
function fetchData(cb: Cb) {
  setTimeout(() => cb(null, 'wrong data'), 1000);
}

test('the data is peanut butter', (done) => {
  function callback(error: {} | null, data: string) {
    if (error) {
      done(error);
      return;
    }

    expect(data).toBe('peanut butter');
    done();
  }

  fetchData(callback);

});
```